<?xml version="1.0"?>
<robot name="khr22"
       xmlns:xi="http://www.w3.org/2001/XInclude">
  <link name="BODY">
    <visual>
      <origin xyz="0 0 0" rpy="0 -0 0"/>
      <!-- <origin xyz="0.0013 0 0.28866" rpy="0 -0 0"/> -->
      <geometry>
        <mesh filename="khr22/mesh/BODY_mesh_refined.dae" scale="1 1 1" />
      </geometry>
    </visual>
    <collision>
      <origin xyz="0 0 0" rpy="0 -0 0"/>
      <!-- <origin xyz="0.0013 0 0.28866" rpy="0 -0 0"/> -->
      <geometry>
        <mesh filename="khr22/mesh/BODY_mesh_refined.dae" scale="1 1 1" />
      </geometry>
    </collision>
    <inertial>
      <mass value="0.12849" />
      <origin xyz="-0.0115 3.53916e-18 -0.02" rpy="0 -0 0"/>
      <inertia ixx="4.39672e-05" ixy="-5.24819e-23" ixz="-6.69555e-24" iyy="9.84623e-05" iyz="-1.72206e-20" izz="9.60387e-05"/>
    </inertial>
  </link>
  <link name="LLEG_LINK0">
    <visual>
      <origin xyz="0 -0.022 0.04" rpy="0 -0 0"/>
      <geometry>
        <mesh filename="khr22/mesh/LLEG_LINK0_mesh_refined.dae" scale="1 1 1" />
      </geometry>
    </visual>
    <collision>
      <origin xyz="0 -0.022 0.04" rpy="0 -0 0"/>
      <geometry>
        <mesh filename="khr22/mesh/LLEG_LINK0_mesh_refined.dae" scale="1 1 1" />
      </geometry>
    </collision>
    <inertial>
      <mass value="0.003322" />
      <origin xyz="-0.001629 -0.001057 -0.009271" rpy="0 -0 0"/>
      <inertia ixx="1.0684e-05" ixy="2.25136e-07" ixz="-7.55589e-09" iyy="1.17667e-05" iyz="-4.21048e-08" izz="4.59644e-06"/>
    </inertial>
  </link>
  <link name="LLEG_LINK1">
    <visual>
      <origin xyz="0.018517 0.017 -0.06265" rpy="0 -0 0"/>
      <geometry>
        <mesh filename="khr22/mesh/LLEG_LINK1_mesh_refined.dae" scale="1 1 1" />
      </geometry>
    </visual>
    <collision>
      <origin xyz="0.018517 0.017 -0.06265" rpy="0 -0 0"/>
      <geometry>
        <mesh filename="khr22/mesh/LLEG_LINK1_mesh_refined.dae" scale="1 1 1" />
      </geometry>
    </collision>
    <inertial>
      <mass value="0.0699" />
      <origin xyz="-0.021734 0.011506 -0.014091" rpy="0 -0 0"/>
      <inertia ixx="1.6919e-05" ixy="-8.67462e-08" ixz="-1.21724e-08" iyy="1.58948e-05" iyz="-5.7174e-07" izz="9.6286e-06"/>
      <!-- <mass value="0.059469" /> -->
      <!-- <origin xyz="-0.02 0.0115 -0.006481" rpy="0 -0 0"/> -->
      <!-- <inertia ixx="6.45473e-05" ixy="-4.27652e-10" ixz="4.33505e-10" iyy="7.31302e-05" iyz="2.22978e-08" izz="4.57654e-05"/> -->
    </inertial>
  </link>
  <link name="LLEG_LINK2">
    <visual>
      <origin xyz="-0.0192 -0.00825 -0.0385" rpy="0 -0 0"/>
      <geometry>
        <mesh filename="khr22/mesh/LLEG_LINK2_mesh_refined.dae" scale="1 1 1" />
      </geometry>
    </visual>
    <collision>
      <origin xyz="-0.0192 -0.00825 -0.0385" rpy="0 -0 0"/>
      <geometry>
        <mesh filename="khr22/mesh/LLEG_LINK2_mesh_refined.dae" scale="1 1 1" />
      </geometry>
    </collision>
    <inertial>
      <mass value="0.1031" />
      <origin xyz="0.002871 0.018978 -0.033258" rpy="0 -0 0"/>
      <inertia ixx="5.51675e-05" ixy="-4.33138e-07" ixz="1.60787e-07" iyy="5.51001e-05" iyz="2.79276e-08" izz="1.42107e-05"/>
      <!-- <mass value="0.08566" /> -->
      <!-- <origin xyz="0.002875 0.02 -0.03327" rpy="0 -0 0"/> -->
      <!-- <inertia ixx="6.70633e-05" ixy="2.76374e-22" ixz="-1.9933e-23" iyy="0.000102" iyz="2.47851e-20" izz="6.47926e-05"/> -->
    </inertial>
  </link>
  <link name="LLEG_LINK3">
    <visual>
      <origin xyz="0 0 -0.065" rpy="0 -0 0"/>
      <geometry>
        <mesh filename="khr22/mesh/LLEG_LINK3_mesh_refined.dae" scale="1 1 1" />
      </geometry>
    </visual>
    <collision>
      <origin xyz="0 0 -0.065" rpy="0 -0 0"/>
      <geometry>
        <mesh filename="khr22/mesh/LLEG_LINK3_mesh_refined.dae" scale="1 1 1" />
      </geometry>
    </collision>
    <inertial>
      <mass value="0.0694" />
      <origin xyz="0.003613 0.016674 -0.031461" rpy="0 -0 0"/>
      <inertia ixx="3.675e-05" ixy="-1.69837e-07" ixz="-8.70062e-07" iyy="3.37577e-05" iyz="-1.30046e-07" izz="1.29244e-05"/>
      <!-- <mass value="0.059469" /> -->
      <!-- <origin xyz="0.005048 0.02 -0.042868" rpy="0 -0 0"/> -->
      <!-- <inertia ixx="0.000211" ixy="-4.27652e-10" ixz="-4.35972e-07" iyy="0.000219" iyz="2.22978e-08" izz="4.55794e-05"/> -->
    </inertial>
  </link>
  <link name="LLEG_LINK4">
    <visual>
      <origin xyz="0 0 -0.065" rpy="0 -0 0"/>
      <geometry>
        <mesh filename="khr22/mesh/LLEG_LINK4_mesh_refined.dae" scale="1 1 1" />
      </geometry>
    </visual>
    <collision>
      <origin xyz="0 0 -0.065" rpy="0 -0 0"/>
      <geometry>
        <mesh filename="khr22/mesh/LLEG_LINK4_mesh_refined.dae" scale="1 1 1" />
      </geometry>
    </collision>
    <inertial>
      <mass value="0.0691" />
      <origin xyz="-0.000386 0.016666 -0.024369" rpy="0 -0 0"/>
      <inertia ixx="1.89725e-05" ixy="-5.30464e-08" ixz="-3.88994e-07" iyy="1.73695e-05" iyz="-1.9347e-08" izz="1.22922e-05"/>
      <!-- <mass value="0.059469" /> -->
      <!-- <origin xyz="-1.0842e-18 0.02 -0.032159" rpy="0 -0 0"/> -->
      <!-- <inertia ixx="0.000349" ixy="-4.27652e-10" ixz="4.33505e-10" iyy="0.000358" iyz="2.22978e-08" izz="4.5842e-05"/> -->
    </inertial>
  </link>
  <link name="LLEG_LINK5">
    <visual>
      <!-- <origin xyz="0.0 0.0 0.0" rpy="0 -0 0"/> -->
      <origin xyz="0.019683 0.00825 -0.0385" rpy="0 -0 0"/>
      <geometry>
        <mesh filename="khr22/mesh/LLEG_LINK5_mesh_sole_ver1.dae" scale="1 1 1" />
      </geometry>
    </visual>
    <collision>
      <!-- <origin xyz="0.0 0.0 0.0" rpy="0 -0 0"/> -->
      <origin xyz="0.019683 0.00825 -0.0385" rpy="0 -0 0"/>
      <geometry>
        <mesh filename="khr22/mesh/LLEG_LINK5_mesh_sole_ver1.dae" scale="1 1 1" />
      </geometry>
    </collision>
    <inertial>
      <mass value="0.0419" />
      <origin xyz="-0.020862 0.020902 -0.013459" rpy="0 -0 0"/>
      <inertia ixx="1.31439e-05" ixy="-3.43305e-09" ixz="-2.13264e-07" iyy="2.75629e-05" iyz="3.99808e-07" izz="3.78492e-05"/>
      <!-- <mass value="0.103233" /> -->
      <!-- <origin xyz="3.46945e-18 0.01093 0.00521" rpy="0 -0 0"/> -->
      <!-- <inertia ixx="0.000993" ixy="4.72528e-06" ixz="-1.08944e-06" iyy="0.000411" iyz="1.03972e-06" izz="0.000602"/> -->
    </inertial>
  </link>
  <link name="RLEG_LINK0">
    <visual>
      <origin xyz="0 0.022 0.04" rpy="0 -0 0"/>
      <geometry>
        <mesh filename="khr22/mesh/RLEG_LINK0_mesh_refined.dae" scale="1 1 1" />
      </geometry>
    </visual>
    <collision>
      <origin xyz="0 0.022 0.04" rpy="0 -0 0"/>
      <geometry>
        <mesh filename="khr22/mesh/RLEG_LINK0_mesh_refined.dae" scale="1 1 1" />
      </geometry>
    </collision>
    <inertial>
      <mass value="0.003322" />
      <origin xyz="-0.001629 0.001057 -0.009271" rpy="0 -0 0"/>
      <inertia ixx="1.0684e-05" ixy="2.25136e-07" ixz="-8.02116e-09" iyy="1.17667e-05" iyz="4.20715e-08" izz="4.59644e-06"/>
    </inertial>
  </link>
  <link name="RLEG_LINK1">
    <visual>
      <origin xyz="0.018517 -0.017 -0.06265" rpy="0 -0 0"/>
      <geometry>
        <mesh filename="khr22/mesh/RLEG_LINK1_mesh_refined.dae" scale="1 1 1" />
      </geometry>
    </visual>
    <collision>
      <origin xyz="0.018517 -0.017 -0.06265" rpy="0 -0 0"/>
      <geometry>
        <mesh filename="khr22/mesh/RLEG_LINK1_mesh_refined.dae" scale="1 1 1" />
      </geometry>
    </collision>
    <inertial>
      <mass value="0.0699" />
      <origin xyz="-0.021734 -0.011506 -0.014091" rpy="0 -0 0"/>
      <inertia ixx="1.67706e-05" ixy="3.09063e-07" ixz="-9.06368e-08" iyy="1.59351e-05" iyz="-1.85881e-07" izz="8.90141e-06"/>
      <!-- <mass value="0.059469" /> -->
      <!-- <origin xyz="-0.02 -0.0115 -0.006481" rpy="0 -0 0"/> -->
      <!-- <inertia ixx="6.45473e-05" ixy="-4.27652e-10" ixz="4.33505e-10" iyy="7.31302e-05" iyz="2.22978e-08" izz="4.57654e-05"/> -->
    </inertial>
  </link>
  <link name="RLEG_LINK2">
    <visual>
      <origin xyz="-0.0192 0.00825 -0.0385" rpy="0 -0 0"/>
      <geometry>
        <mesh filename="khr22/mesh/RLEG_LINK2_mesh_refined.dae" scale="1 1 1" />
      </geometry>
    </visual>
    <collision>
      <origin xyz="-0.0192 0.00825 -0.0385" rpy="0 -0 0"/>
      <geometry>
        <mesh filename="khr22/mesh/RLEG_LINK2_mesh_refined.dae" scale="1 1 1" />
      </geometry>
    </collision>
    <inertial>
      <mass value="0.1031" />
      <origin xyz="0.002871 -0.018978 -0.033258" rpy="0 -0 0"/>
      <inertia ixx="5.53682e-05" ixy="1.79727e-07" ixz="1.50432e-07" iyy="5.49684e-05" iyz="-1.26323e-07" izz="1.5723e-05"/>
      <!-- <mass value="0.08566" /> -->
      <!-- <origin xyz="0.002875 -0.02 -0.03327" rpy="0 -0 0"/> -->
      <!-- <inertia ixx="6.70633e-05" ixy="2.76374e-22" ixz="-1.9933e-23" iyy="0.000102" iyz="2.47851e-20" izz="6.47926e-05"/> -->
    </inertial>
  </link>
  <link name="RLEG_LINK3">
    <visual>
      <origin xyz="0 0 -0.065" rpy="0 -0 0"/>
      <geometry>
        <mesh filename="khr22/mesh/RLEG_LINK3_mesh_refined.dae" scale="1 1 1" />
      </geometry>
    </visual>
    <collision>
      <origin xyz="0 0 -0.065" rpy="0 -0 0"/>
      <geometry>
        <mesh filename="khr22/mesh/RLEG_LINK3_mesh_refined.dae" scale="1 1 1" />
      </geometry>
    </collision>
    <inertial>
      <mass value="0.0694" />
      <origin xyz="0.003613 -0.016674 -0.031461" rpy="0 -0 0"/>
      <inertia ixx="3.88163e-05" ixy="-4.03699e-09" ixz="-8.68336e-07" iyy="3.51562e-05" iyz="-8.44442e-08" izz="1.3848e-05"/>
      <!-- <mass value="0.059469" /> -->
      <!-- <origin xyz="0.005048 -0.02 -0.042868" rpy="0 -0 0"/> -->
      <!-- <inertia ixx="0.000211" ixy="-4.27652e-10" ixz="-4.35972e-07" iyy="0.000219" iyz="2.22978e-08" izz="4.55794e-05"/> -->
    </inertial>
  </link>
  <link name="RLEG_LINK4">
    <visual>
      <origin xyz="0 -0.003 -0.065" rpy="0 -0 0"/>
      <geometry>
        <mesh filename="khr22/mesh/RLEG_LINK4_mesh_refined.dae" scale="1 1 1" />
      </geometry>
    </visual>
    <collision>
      <origin xyz="0 -0.003 -0.065" rpy="0 -0 0"/>
      <geometry>
        <mesh filename="khr22/mesh/RLEG_LINK4_mesh_refined.dae" scale="1 1 1" />
      </geometry>
    </collision>
    <inertial>
      <mass value="0.0691" />
      <origin xyz="-0.000386 -0.016666 -0.024369" rpy="0 -0 0"/>
      <inertia ixx="2.07911e-05" ixy="-1.95431e-07" ixz="9.83503e-08" iyy="1.81828e-05" iyz="8.03039e-08" izz="1.18297e-05"/>
      <!-- <mass value="0.059469" /> -->
      <!-- <origin xyz="-4.33681e-19 -0.02 -0.032159" rpy="0 -0 0"/> -->
      <!-- <inertia ixx="0.000349" ixy="-4.27652e-10" ixz="4.33505e-10" iyy="0.000358" iyz="2.22978e-08" izz="4.5842e-05"/> -->
    </inertial>
  </link>
  <link name="RLEG_LINK5">
    <visual>
      <!-- <origin xyz="0.0 0.0 0.0" rpy="0 -0 0"/> -->
      <origin xyz="0.019683 -0.00825 -0.0385" rpy="0 -0 0"/>
      <geometry>
        <mesh filename="khr22/mesh/RLEG_LINK5_mesh_sole_ver1.dae" scale="1 1 1" />
      </geometry>
    </visual>
    <collision>
      <!-- <origin xyz="0.0 0.0 0.0" rpy="0 -0 0"/> -->
      <origin xyz="0.019683 -0.00825 -0.0385" rpy="0 -0 0"/>
      <geometry>
        <mesh filename="khr22/mesh/RLEG_LINK5_mesh_sole_ver1.dae" scale="1 1 1" />
      </geometry>
    </collision>
    <inertial>
      <mass value="0.0419" />
      <origin xyz="-0.020862 -0.020902 -0.013459" rpy="0 -0 0"/>
      <inertia ixx="1.24417e-05" ixy="-6.00499e-07" ixz="1.04282e-07" iyy="3.00021e-05" iyz="-5.79267e-07" izz="3.92743e-05"/>
      <!-- <mass value="0.103233" /> -->
      <!-- <origin xyz="-3.46945e-18 -0.01093 0.00521" rpy="0 -0 0"/> -->
      <!-- <inertia ixx="0.000993" ixy="4.72527e-06" ixz="1.01251e-06" iyy="0.000411" iyz="-1.52142e-07" izz="0.000602"/> -->
    </inertial>
  </link>
  <link name="TORSO_LINK0">
    <visual>
      <origin xyz="0 0 0" rpy="0 -0 0"/>
      <geometry>
        <mesh filename="khr22/mesh/TORSO_LINK0_mesh_refined.dae" scale="1 1 1" />
      </geometry>
    </visual>
    <collision>
      <origin xyz="0 0 0" rpy="0 -0 0"/>
      <geometry>
        <mesh filename="khr22/mesh/TORSO_LINK0_mesh_refined.dae" scale="1 1 1" />
      </geometry>
    </collision>
    <inertial>
      <mass value="0.35983" />
      <origin xyz="-0.029892 1.89568e-17 0.029281" rpy="0 -0 0"/>
      <inertia ixx="0.002007" ixy="3.87489e-05" ixz="-9.86728e-07" iyy="0.001856" iyz="-7.26528e-06" izz="0.001515"/>
    </inertial>
  </link>
  <link name="HEAD_LINK0">
    <visual>
      <origin xyz="0 0 0.0644" rpy="0 -0 0"/>
      <geometry>
        <mesh filename="khr22/mesh/HEAD_LINK0_mesh_refined.dae" scale="1 1 1" />
      </geometry>
    </visual>
    <collision>
      <origin xyz="0 0 0.0644" rpy="0 -0 0"/>
      <geometry>
        <mesh filename="khr22/mesh/HEAD_LINK0_mesh_refined.dae" scale="1 1 1" />
      </geometry>
    </collision>
    <inertial>
      <mass value="0.0149" />
      <origin xyz="0.002048 0 0.020747" rpy="0 -0 0"/>
      <inertia ixx="1.89498e-06" ixy="1.75751e-08" ixz="-5.79694e-08" iyy="3.27018e-06" iyz="1.69379e-08" izz="2.44034e-06"/>
      <!-- <mass value="0.014361" /> -->
      <!-- <origin xyz="0.003285 -2.30629e-06 0.020555" rpy="0 -0 0"/> -->
      <!-- <inertia ixx="4.95528e-05" ixy="-1.38168e-11" ixz="-7.3432e-08" iyy="4.45537e-05" iyz="-2.01845e-09" izz="1.47912e-05"/> -->
    </inertial>
  </link>
  <link name="LARM_LINK0">
    <visual>
      <origin xyz="0.0115 0.049 0.0474" rpy="0 -0 0"/>
      <geometry>
        <mesh filename="khr22/mesh/LARM_LINK0_mesh_refined.dae" scale="1 1 1" />
      </geometry>
    </visual>
    <collision>
      <origin xyz="0.0115 0.049 0.0474" rpy="0 -0 0"/>
      <geometry>
        <mesh filename="khr22/mesh/LARM_LINK0_mesh_refined.dae" scale="1 1 1" />
      </geometry>
    </collision>
    <inertial>
      <mass value="0.0153" />
      <origin xyz="0 0.014576 0" rpy="0 -0 0"/>
      <inertia ixx="1.64238e-06" ixy="-4.39899e-09" ixz="2.13134e-08" iyy="2.26922e-06" iyz="-3.47822e-09" izz="2.75336e-06"/>
      <!-- <mass value="0.016639" /> -->
      <!-- <origin xyz="-3.46945e-18 0.009163 0" rpy="0 -0 0"/> -->
      <!-- <inertia ixx="3.04092e-05" ixy="-4.27652e-10" ixz="4.33505e-10" iyy="2.27027e-05" iyz="2.22978e-08" izz="2.23763e-05"/> -->
    </inertial>
  </link>
  <link name="LARM_LINK1">
    <visual>
      <origin xyz="0.01975 0.0255 0" rpy="0 -0 0"/>
      <geometry>
        <mesh filename="khr22/mesh/LARM_LINK1_mesh_refined.dae" scale="1 1 1" />
      </geometry>
    </visual>
    <collision>
      <origin xyz="0.01975 0.0255 0" rpy="0 -0 0"/>
      <geometry>
        <mesh filename="khr22/mesh/LARM_LINK1_mesh_refined.dae" scale="1 1 1" />
      </geometry>
    </collision>
    <inertial>
      <mass value="0.08566" />
      <origin xyz="-0.02425 0 -0.03275" rpy="0 -0 0"/>
      <inertia ixx="4.0299e-05" ixy="-8.32865e-25" ixz="-3.89972e-23" iyy="6.60435e-05" iyz="9.2227e-21" izz="7.43506e-05"/>
    </inertial>
  </link>
  <link name="LARM_LINK2">
    <visual>
      <origin xyz="0.04025 0.0255 0.075" rpy="0 -0 0"/>
      <!-- <origin xyz="-0.016 0 -0.075" rpy="0 -0 0"/> -->
      <geometry>
        <mesh filename="khr22/mesh/LARM_LINK2_mesh_refined.dae" scale="1 1 1" />
      </geometry>
    </visual>
    <collision>
      <origin xyz="0.04025 0.0255 0.075" rpy="0 -0 0"/>
      <!-- <origin xyz="-0.016 0 -0.075" rpy="0 -0 0"/> -->
      <geometry>
        <mesh filename="khr22/mesh/LARM_LINK2_mesh_refined.dae" scale="1 1 1" />
      </geometry>
    </collision>
    <inertial>
      <mass value="0.04283" />
      <origin xyz="0.0115 0 1.04083e-17" rpy="0 -0 0"/>
      <inertia ixx="2.11725e-05" ixy="4.25575e-26" ixz="-1.88949e-23" iyy="3.40543e-05" iyz="1.04267e-20" izz="3.71848e-05"/>
    </inertial>
  </link>
  <link name="LARM_LINK3">
    <visual>
      <origin xyz="-0.0153 -0.0197 -0.0875" rpy="0 -0 0"/>
      <geometry>
        <mesh filename="khr22/mesh/LARM_LINK3_mesh_refined.dae" scale="1 1 1" />
      </geometry>
    </visual>
    <collision>
      <origin xyz="-0.0153 -0.0197 -0.0875" rpy="0 -0 0"/>
      <geometry>
        <mesh filename="khr22/mesh/LARM_LINK3_mesh_refined.dae" scale="1 1 1" />
      </geometry>
    </collision>
    <inertial>
      <mass value="0.0315" />
      <origin xyz="0.000525 0.019115 -0.039067" rpy="0 -0 0"/>
      <inertia ixx="2.0635e-05" ixy="6.63534e-08" ixz="1.858e-07" iyy="1.94974e-05" iyz="-1.80473e-07" izz="3.50615e-06"/>
      <!-- <mass value="0.07626" /> -->
      <!-- <origin xyz="0.020363 0.074486 -0.077361" rpy="0 -0 0"/> -->
      <!-- <inertia ixx="0.000144" ixy="4.76604e-08" ixz="1.40919e-07" iyy="0.000121" iyz="-4.90624e-08" izz="9.78235e-05"/> -->
    </inertial>
  </link>
  <link name="RARM_LINK0">
    <visual>
      <origin xyz="0.0115 -0.049 0.0474" rpy="0 -0 0"/>
      <geometry>
        <mesh filename="khr22/mesh/RARM_LINK0_mesh_refined.dae" scale="1 1 1" />
      </geometry>
    </visual>
    <collision>
      <origin xyz="0.0115 -0.049 0.0474" rpy="0 -0 0"/>
      <geometry>
        <mesh filename="khr22/mesh/RARM_LINK0_mesh_refined.dae" scale="1 1 1" />
      </geometry>
    </collision>
    <inertial>
      <mass value="0.0153" />
      <origin xyz="0 -0.014576 0" rpy="0 -0 0"/>
      <inertia ixx="1.6763e-06" ixy="-1.67661e-08" ixz="-9.95332e-09" iyy="2.26307e-06" iyz="1.99264e-09" izz="2.74554e-06"/>
      <!-- <mass value="0.016639" /> -->
      <!-- <origin xyz="0 -0.009163 0" rpy="0 -0 0"/> -->
      <!-- <inertia ixx="3.04092e-05" ixy="-4.27652e-10" ixz="4.33505e-10" iyy="2.27027e-05" iyz="2.22978e-08" izz="2.23763e-05"/> -->
    </inertial>
  </link>
  <link name="RARM_LINK1">
    <visual>
      <origin xyz="0.01975 -0.0255 0" rpy="0 -0 0"/>
      <geometry>
        <mesh filename="khr22/mesh/RARM_LINK1_mesh_refined.dae" scale="1 1 1" />
      </geometry>
    </visual>
    <collision>
      <origin xyz="0.01975 -0.0255 0" rpy="0 -0 0"/>
      <geometry>
        <mesh filename="khr22/mesh/RARM_LINK1_mesh_refined.dae" scale="1 1 1" />
      </geometry>
    </collision>
    <inertial>
      <mass value="0.08566" />
      <origin xyz="-0.02425 0 -0.03275" rpy="0 -0 0"/>
      <inertia ixx="4.0299e-05" ixy="-8.32865e-25" ixz="-3.89972e-23" iyy="6.60435e-05" iyz="9.2227e-21" izz="7.43506e-05"/>
    </inertial>
  </link>
  <link name="RARM_LINK2">
    <visual>
      <origin xyz="0.04025 -0.0255 0.075" rpy="0 -0 0"/>
      <!-- <origin xyz="-0.016 0 -0.075" rpy="0 -0 0"/> -->
      <geometry>
        <mesh filename="khr22/mesh/RARM_LINK2_mesh_refined.dae" scale="1 1 1" />
      </geometry>
    </visual>
    <collision>
      <origin xyz="0.04025 -0.0255 0.075" rpy="0 -0 0"/>
      <!-- <origin xyz="-0.016 0 -0.075" rpy="0 -0 0"/> -->
      <geometry>
        <mesh filename="khr22/mesh/RARM_LINK2_mesh_refined.dae" scale="1 1 1" />
      </geometry>
    </collision>
    <inertial>
      <mass value="0.04283" />
      <origin xyz="0.0115 0 1.04083e-17" rpy="0 -0 0"/>
      <inertia ixx="2.11725e-05" ixy="4.25575e-26" ixz="-1.88949e-23" iyy="3.40543e-05" iyz="1.04267e-20" izz="3.71848e-05"/>
    </inertial>
  </link>
  <link name="RARM_LINK3">
    <visual>
      <origin xyz="-0.0153 0.0197 -0.0875" rpy="0 -0 0"/>
      <geometry>
        <mesh filename="khr22/mesh/RARM_LINK3_mesh_refined.dae" scale="1 1 1" />
      </geometry>
    </visual>
    <collision>
      <origin xyz="-0.0153 0.0197 -0.0875" rpy="0 -0 0"/>
      <geometry>
        <mesh filename="khr22/mesh/RARM_LINK3_mesh_refined.dae" scale="1 1 1" />
      </geometry>
    </collision>
    <inertial>
      <mass value="0.0315" />
      <origin xyz="0.000525 -0.019115 -0.039067" rpy="0 -0 0"/>
      <inertia ixx="2.01586e-05" ixy="-1.18985e-07" ixz="7.55844e-08" iyy="1.8365e-05" iyz="5.07189e-07" izz="4.02757e-06"/>
      <!-- <mass value="0.07626" /> -->
      <!-- <origin xyz="0.020363 -0.074486 -0.077361" rpy="0 -0 0"/> -->
      <!-- <inertia ixx="0.000144" ixy="4.76604e-08" ixz="1.7102e-07" iyy="0.000121" iyz="8.96584e-08" izz="9.78235e-05"/> -->
    </inertial>
  </link>
  <joint name="LLEG_JOINT0" type="revolute">
    <parent link="BODY"/>
    <child  link="LLEG_LINK0"/>
    <origin xyz="0 0.022 -0.04" rpy="0 -0 0 "/>
    <axis   xyz="0 0 1"/>
    <limit lower="-0.7854" upper="1.5708" effort="2.5" velocity="10.0" />
    <dynamics damping="0.2" friction="0" />
  </joint>
  <joint name="LLEG_JOINT1" type="revolute">
    <parent link="LLEG_LINK0"/>
    <child  link="LLEG_LINK1"/>
    <origin xyz="0.02 -0.005 -0.0235" rpy="0 -0 0 "/>
    <axis   xyz="1 0 0"/>
    <limit lower="-0.2618" upper="0.5236" effort="2.5" velocity="10.0" />
    <dynamics damping="0.2" friction="0" />
  </joint>
  <joint name="LLEG_JOINT2" type="revolute">
    <parent link="LLEG_LINK1"/>
    <child  link="LLEG_LINK2"/>
    <origin xyz="-0.021 -0.00825 -0.0385" rpy="0 -0 0 "/>
    <axis   xyz="0 1 0"/>
    <limit lower="-1.5708" upper="1.5708" effort="2.5" velocity="10.0" />
    <dynamics damping="0.2" friction="0" />
  </joint>
  <joint name="LLEG_JOINT3" type="revolute">
    <parent link="LLEG_LINK2"/>
    <child  link="LLEG_LINK3"/>
    <origin xyz="0 0 -0.065" rpy="0 -0 0 "/>
    <axis   xyz="0 1 0"/>
    <limit lower="0.0" upper="2.6180" effort="2.5" velocity="10.0" />
    <dynamics damping="0.2" friction="0" />
  </joint>
  <joint name="LLEG_JOINT4" type="revolute">
    <parent link="LLEG_LINK3"/>
    <child  link="LLEG_LINK4"/>
    <origin xyz="0 0 -0.065" rpy="0 -0 0 "/>
    <axis   xyz="0 1 0"/>
    <limit lower="-1.8326" upper="2.3561" effort="2.5" velocity="10.0" />
    <dynamics damping="0.2" friction="0" />
  </joint>
  <joint name="LLEG_JOINT5" type="revolute">
    <parent link="LLEG_LINK4"/>
    <child  link="LLEG_LINK5"/>
    <origin xyz="0.0197 0.00825 -0.0385" rpy="0 -0 0 "/>
    <axis   xyz="1 0 0"/>
    <limit lower="-0.5236" upper="0.0" effort="2.5" velocity="10.0" />
    <dynamics damping="0.2" friction="0" />
  </joint>
  <joint name="RLEG_JOINT0" type="revolute">
    <parent link="BODY"/>
    <child  link="RLEG_LINK0"/>
    <origin xyz="0 -0.022 -0.04" rpy="0 -0 0 "/>
    <axis   xyz="0 0 1"/>
    <limit lower="-1.5708" upper="0.7854" effort="2.5" velocity="10.0" />
    <dynamics damping="0.2" friction="0" />
  </joint>
  <joint name="RLEG_JOINT1" type="revolute">
    <parent link="RLEG_LINK0"/>
    <child  link="RLEG_LINK1"/>
    <origin xyz="0.02 0.005 -0.0235" rpy="0 -0 0 "/>
    <axis   xyz="1 0 0"/>
    <limit lower="-0.5236" upper="0.2618" effort="2.5" velocity="10.0" />
    <dynamics damping="0.2" friction="0" />
  </joint>
  <joint name="RLEG_JOINT2" type="revolute">
    <parent link="RLEG_LINK1"/>
    <child  link="RLEG_LINK2"/>
    <origin xyz="-0.021 0.00825 -0.0385" rpy="0 -0 0 "/>
    <axis   xyz="0 1 0"/>
    <limit lower="-1.5708" upper="1.5708" effort="2.5" velocity="10.0" />
    <dynamics damping="0.2" friction="0" />
  </joint>
  <joint name="RLEG_JOINT3" type="revolute">
    <parent link="RLEG_LINK2"/>
    <child  link="RLEG_LINK3"/>
    <origin xyz="0 0 -0.065" rpy="0 -0 0 "/>
    <axis   xyz="0 1 0"/>
    <limit lower="0.0" upper="2.6108" effort="2.5" velocity="10.0" />
    <dynamics damping="0.2" friction="0" />
  </joint>
  <joint name="RLEG_JOINT4" type="revolute">
    <parent link="RLEG_LINK3"/>
    <child  link="RLEG_LINK4"/>
    <origin xyz="0 0 -0.065" rpy="0 -0 0 "/>
    <axis   xyz="0 1 0"/>
    <limit lower="-1.8326" upper="2.3561" effort="2.5" velocity="10.0" />
    <dynamics damping="0.2" friction="0" />
  </joint>
  <joint name="RLEG_JOINT5" type="revolute">
    <parent link="RLEG_LINK4"/>
    <child  link="RLEG_LINK5"/>
    <origin xyz="0.0197 -0.00825 -0.0385" rpy="0 -0 0 "/>
    <axis   xyz="1 0 0"/>
    <limit lower="0.0" upper="0.5236" effort="2.5" velocity="10.0" />
    <dynamics damping="0.2" friction="0" />
  </joint>
  <joint name="TORSO_JOINT0" type="revolute">
    <parent link="BODY"/>
    <child  link="TORSO_LINK0"/>
    <origin xyz="0 0 0" rpy="0 -0 0 "/>
    <axis   xyz="0 0 1"/>
    <limit lower="-1.5708" upper="1.5708" effort="2.5" velocity="10.0" />
    <dynamics damping="0.2" friction="0" />
  </joint>
  <joint name="HEAD_JOINT0" type="fixed">
    <parent link="TORSO_LINK0"/>
    <child  link="HEAD_LINK0"/>
    <origin xyz="0.0115 0 0.064" rpy="0 -0 0 "/>
    <axis   xyz="0 0 1"/>
    <limit lower="-2.3562" upper="2.3562" effort="2.5" velocity="10.0" />
    <dynamics damping="0.2" friction="0" />
  </joint>
  <joint name="LARM_JOINT0" type="revolute">
    <parent link="TORSO_LINK0"/>
    <child  link="LARM_LINK0"/>
    <origin xyz="0.0115 0.049 0.0474" rpy="0 -0 0 "/>
    <axis   xyz="0 1 0"/>
    <limit lower="-3.1416" upper="0.7854" effort="2.5" velocity="10.0" />
    <dynamics damping="0.2" friction="0" />
  </joint>
  <joint name="LARM_JOINT1" type="revolute">
    <parent link="LARM_LINK0"/>
    <child  link="LARM_LINK1"/>
    <origin xyz="0.01975 0.0255 0" rpy="0 -0 0 "/>
    <axis   xyz="1 0 0"/>
    <limit lower="-0.5236" upper="3.1416" effort="2.5" velocity="10.0" />
    <dynamics damping="0.2" friction="0" />
  </joint>
  <joint name="LARM_JOINT2" type="revolute">
    <parent link="LARM_LINK1"/>
    <child  link="LARM_LINK2"/>
    <origin xyz="-0.0205 0 -0.075" rpy="0 -0 0 "/>
    <!-- <origin xyz="-0.016 0 -0.075" rpy="0 -0 0 "/> -->
    <axis   xyz="0 0 1"/>
    <limit lower="-2.3562" upper="2.3562" effort="2.5" velocity="10.0" />
    <dynamics damping="0.2" friction="0" />
  </joint>
  <joint name="LARM_JOINT3" type="revolute">
    <parent link="LARM_LINK2"/>
    <child  link="LARM_LINK3"/>
    <origin xyz="0.005 -0.02 -0.0125" rpy="0 -0 0 "/>
    <!-- <origin xyz="0.005 -0.02 -0.0135" rpy="0 -0 0 "/> -->
    <axis   xyz="0 1 0"/>
    <limit lower="-2.0944" upper="0.0" effort="2.5" velocity="10.0" />
    <dynamics damping="0.2" friction="0" />
  </joint>
  <joint name="RARM_JOINT0" type="revolute">
    <parent link="TORSO_LINK0"/>
    <child  link="RARM_LINK0"/>
    <origin xyz="0.0115 -0.049 0.0474" rpy="0 -0 0 "/>
    <axis   xyz="0 1 0"/>
    <limit lower="-3.1416" upper="0.7854" effort="2.5" velocity="10.0" />
    <dynamics damping="0.2" friction="0" />
  </joint>
  <joint name="RARM_JOINT1" type="revolute">
    <parent link="RARM_LINK0"/>
    <child  link="RARM_LINK1"/>
    <origin xyz="0.01975 -0.0255 0" rpy="0 -0 0 "/>
    <axis   xyz="1 0 0"/>
    <limit lower="-3.1416" upper="0.5236" effort="2.5" velocity="10.0" />
    <dynamics damping="0.2" friction="0" />
  </joint>
  <joint name="RARM_JOINT2" type="revolute">
    <parent link="RARM_LINK1"/>
    <child  link="RARM_LINK2"/>
    <origin xyz="-0.0205 0 -0.075" rpy="0 -0 0 "/>
    <!-- <origin xyz="-0.016 0 -0.075" rpy="0 -0 0 "/> -->
    <axis   xyz="0 0 1"/>
    <limit lower="-2.3562" upper="2.3562" effort="2.5" velocity="10.0" />
    <dynamics damping="0.2" friction="0" />
  </joint>
  <joint name="RARM_JOINT3" type="revolute">
    <parent link="RARM_LINK2"/>
    <child  link="RARM_LINK3"/>
    <origin xyz="0.005 0.02 -0.0125" rpy="0 -0 0 "/>
    <!-- <origin xyz="0.005 0.02 -0.0135" rpy="0 -0 0 "/> -->
    <axis   xyz="0 1 0"/>
    <limit lower="-2.0944" upper="0.0" effort="2.5" velocity="10.0" />
    <dynamics damping="0.2" friction="0" />
  </joint>
</robot>
