<mujoco model="multisense_sl">
    <compiler angle="radian" />
    <size njmax="500" nconmax="100" />
    <worldbody>
        <geom size="0.11 0.03" pos="0.046 0 0.01" quat="0.707107 0.707107 0 0" type="cylinder" />
        <geom size="0.11 0.03" pos="-0.03 0 0.01" quat="0.707107 0.707107 0 0" type="cylinder" />
        <geom size="0.16 0.025" pos="0.01 0.042 0.09" type="cylinder" />
        <geom size="0.16 0.025" pos="0.01 -0.042 0.09" type="cylinder" />
        <geom size="0.05 0.075 0.1" pos="-0.1 0 -0.02" type="box" />
        <body name="ltorso" pos="-0.0125 0 0">
            <inertial pos="-0.0112984 -3.15366e-06 0.0746835" quat="0.997071 0.000128212 0.076485 -0.00012406" mass="2.27" diaginertia="0.003962 0.00341694 0.00169212" />
            <joint name="back_bkz" pos="0 0 0" axis="0 0 1" limited="true" range="-0.663225 0.663225" damping="0.1" />
            <body name="mtorso" pos="0 0 0.162">
                <inertial pos="-0.00816266 -0.0131245 0.0305974" quat="0.108378 0.49314 0.746335 0.433648" mass="0.799" diaginertia="0.000536243 0.000487378 0.000358057" />
                <joint name="back_bky" pos="0 0 0" axis="0 1 0" limited="true" range="-0.219388 0.538783" damping="0.1" />
                <geom size="0.02 0.075" pos="0 0 0.02" type="cylinder" />
                <body name="utorso" pos="0 0 0.05">
                    <inertial pos="-0.0622 0.0023 0.3157" quat="0.450601 -0.0341277 -0.0439518 0.89099" mass="84.409" diaginertia="1.62425 1.5673 0.552443" />
                    <joint name="back_bkx" pos="0 0 0" axis="1 0 0" limited="true" range="-0.523599 0.523599" damping="0.1" />
                    <geom size="0.2 0.175 0.25" pos="-0.102 0 0.25" type="box" />
                    <geom size="0.065 0.25 0.05" pos="0.2 0 0.46" quat="0.707141 0 0.707073 0" type="box" />
                    <geom size="0.1 0.115 0.05" pos="0.2 0 0.285" quat="0.659983 0 0.75128 0" type="box" />
                    <geom size="0.1 0.09 0.05" pos="0.15 0 0.1" quat="0.540302 0 0.841471 0" type="box" />
                    <geom size="0.253153 0.170859 0.06" pos="-0.035 0 0.6265" type="box" />
                    <geom size="0.008 0.065" pos="0.208 0 0.8215" quat="0.707141 0.707073 0 0" type="cylinder" />
                    <geom size="0.008 0.075" pos="0.208 -0.125 0.745" quat="0.981496 -0.191485 0 0" type="cylinder" />
                    <geom size="0.008 0.075" pos="0.208 0.125 0.745" quat="0.981496 0.191485 0 0" type="cylinder" />
                    <geom size="0.008 0.075" pos="0.063 -0.125 0.745" quat="0.981496 -0.191485 0 0" type="cylinder" />
                    <geom size="0.008 0.075" pos="0.063 0.125 0.745" quat="0.981496 0.191485 0 0" type="cylinder" />
                    <geom size="0.008 0.075" pos="0.14 0.06 0.8215" quat="0.500048 0.5 0.499952 0.5" type="cylinder" />
                    <geom size="0.008 0.075" pos="0.14 -0.06 0.8215" quat="0.500048 0.5 0.499952 0.5" type="cylinder" />
                    <geom size="0.1 0.125 0.005" pos="-0.029 0 0.731" quat="0.947651 0 -0.319309 0" type="box" />
                    <geom size="0.008 0.065" pos="0.063 0 0.8215" quat="0.707141 0.707073 0 0" type="cylinder" />
                    <geom size="0.055 0.008" pos="0.261 0.156 0.6215" quat="0.707141 0.707073 0 0" type="cylinder" />
                    <geom size="0.055 0.008" pos="0.261 -0.156 0.6215" quat="0.707141 0.707073 0 0" type="cylinder" />
                    <body name="l_clav" pos="0.1406 0.2256 0.4776" quat="0 0 0 1">
                        <inertial pos="0 -0.048 -0.084" quat="0.684588 0.177029 -0.177029 0.684588" mass="4.466" diaginertia="0.011217 0.011 0.00178301" />
                        <joint name="l_arm_shz" pos="0 0 0" axis="0 0 1" limited="true" range="-1.5708 0.785398" damping="0.1" />
                        <geom size="0.0555 0.07625" pos="0 -0.11 -0.248" quat="0.707107 0 0.707107 0" type="cylinder" />
                        <geom size="0.067 0.13" pos="0.005 -0.015 -0.08" type="cylinder" />
                        <geom size="0.05 0.035 0.036" pos="0.004 -0.064 -0.247" quat="0.865324 0.501213 0 0" type="box" />
                        <body name="l_scap" pos="0 -0.11 -0.245">
                            <inertial pos="0 0 0" quat="0.5 0.5 0.5 0.5" mass="3.899" diaginertia="0.00583 0.00583 0.00319" />
                            <joint name="l_arm_shx" pos="0 0 0" axis="-1 0 0" limited="true" range="-1.5708 1.5708" damping="0.1" />
                            <geom size="0.057 0.0525" pos="-0.005 -0.115 -0.014" quat="0.707107 0.707107 0 0" type="cylinder" />
                            <geom size="0.08 0.085 0.04" pos="-0.005 -0.075 -0.015" type="box" />
                            <geom size="0.01 0.0145 0.009" pos="0.076 -0.0615 0.0128" quat="0.431177 0.902268 0 0" type="box" />
                            <geom size="0.014 0.045 0.025" pos="-0.075 0.015 0.019" quat="0.877583 0.479426 0 0" type="box" />
                            <body name="l_uarm" pos="0 -0.187 -0.016">
                                <inertial pos="0 0.065 0" quat="0.707107 0.707107 0 0" mass="4.386" diaginertia="0.00656 0.00656 0.00358" />
                                <joint name="l_arm_ely" pos="0 0 0" axis="0 -1 0" limited="true" range="0 3.14159" damping="0.2" />
                                <geom size="0.065 0.055" pos="0 -0.035 0" quat="0.707105 0.707108 0 0" type="cylinder" />
                                <geom size="0.047 0.071" pos="-0.005 -0.111 0.017" quat="0.707105 0 0.707108 0" type="cylinder" />
                                <geom size="0.025 0.035 0.075" pos="-0.001 -0.043 0.01" quat="0.707107 0 0.707107 0" type="box" />
                                <body name="l_larm" pos="0 -0.119 0.0092">
                                    <inertial pos="0 0 0" quat="0.5 0.5 0.5 0.5" mass="3.248" diaginertia="0.00446 0.00446 0.00265" />
                                    <joint name="l_arm_elx" pos="0 0 0" axis="-1 0 0" limited="true" range="0 2.35619" damping="0.2" />
                                    <geom size="0.045 0.0625" pos="0.001 -0.127 0" quat="0.707107 0.707107 0 0" type="cylinder" />
                                    <geom size="0.0675 0.075 0.03" pos="0.001 -0.051 0" type="box" />
                                    <body name="l_ufarm" pos="0 -0.187 -0.0092" quat="0 0 1 0">
                                        <inertial pos="0 0.065 0" quat="0.707107 0.707107 0 0" mass="4.386" diaginertia="0.00656 0.00656 0.00358" />
                                        <joint name="l_arm_wry" pos="0 0 0" axis="0 -1 0" limited="true" range="0 3.14159" damping="0.1" />
                                        <geom size="0.045 0.0625" pos="0 -0.13 0.004" quat="0.707105 0 0.707108 0" type="cylinder" />
                                        <geom size="0.0675 0.05 0.0225" pos="0.001 -0.053 -0.002" type="box" />
                                        <body name="l_lfarm" pos="0 -0.119 0.0092">
                                            <inertial pos="0 0 0" quat="0.5 0.5 0.5 0.5" mass="2.509" diaginertia="0.00446 0.00446 0.00265" />
                                            <joint name="l_arm_wrx" pos="0 0 0" axis="1 0 0" limited="true" range="-1.1781 1.1781" damping="0.1" />
                                            <geom size="0.03 0.025" pos="0.001 -0.1 -0.01" quat="0.707107 0.707107 0 0" type="cylinder" />
                                            <geom size="0.065 0.045 0.035" pos="0.001 -0.05 -0.01" type="box" />
                                            <body name="l_hand" pos="0 0 0" quat="0 0 1 0">
                                                <inertial pos="0 0 0" mass="1" diaginertia="0.0001 0.0001 0.0001" />
                                                <joint name="l_arm_wry2" pos="0 0 0" axis="0 1 0" limited="true" range="-0.001 0.001" damping="0.1" />
                                                <geom size="0.03" pos="0 -0.15 0.01" rgba="1 1 1 1" />
                                            </body>
                                        </body>
                                    </body>
                                </body>
                            </body>
                        </body>
                    </body>
                    <body name="head" pos="0.2546 0 0.6215">
                        <inertial pos="-0.075493 3.3383e-05 0.02774" quat="0.945485 -0.000797655 0.325663 -0.000518426" mass="1.41984" diaginertia="0.00466672 0.0041178 0.00282637" />
                        <joint name="neck_ry" pos="0 0 0" axis="0 1 0" limited="true" range="-0.602139 1.14319" damping="0.1" />
                        <geom size="0.06555 0.06 0.02955" pos="-0.0503 0 -0.00195" type="box" rgba="1 1 1 1" />
                        <geom size="0.0234 0.06 0.0592" pos="-0.093 0 0.0868" type="box" rgba="1 1 1 1" />
                    </body>
                    <body name="r_clav" pos="0.1406 -0.2256 0.4776">
                        <inertial pos="0 -0.048 -0.084" quat="0.684588 0.177029 -0.177029 0.684588" mass="4.466" diaginertia="0.011217 0.011 0.00178301" />
                        <joint name="r_arm_shz" pos="0 0 0" axis="0 0 1" limited="true" range="-0.785398 1.5708" damping="0.1" />
                        <geom size="0.0555 0.07625" pos="0 -0.11 -0.248" quat="0.707107 0 0.707107 0" type="cylinder" />
                        <geom size="0.067 0.13" pos="0.005 -0.015 -0.08" type="cylinder" />
                        <geom size="0.05 0.035 0.036" pos="0.004 -0.064 -0.247" quat="0.865324 0.501213 0 0" type="box" />
                        <body name="r_scap" pos="0 -0.11 -0.245">
                            <inertial pos="0 0 0" quat="0.5 0.5 0.5 0.5" mass="3.899" diaginertia="0.00583 0.00583 0.00319" />
                            <joint name="r_arm_shx" pos="0 0 0" axis="1 0 0" limited="true" range="-1.5708 1.5708" damping="0.1" />
                            <geom size="0.057 0.0525" pos="-0.005 -0.115 -0.014" quat="0.707107 0.707107 0 0" type="cylinder" />
                            <geom size="0.08 0.085 0.04" pos="-0.005 -0.075 -0.015" type="box" />
                            <geom size="0.01 0.0145 0.009" pos="0.076 -0.0615 0.0128" quat="0.431177 0.902268 0 0" type="box" />
                            <geom size="0.014 0.045 0.025" pos="-0.075 0.015 0.019" quat="0.877583 0.479426 0 0" type="box" />
                            <body name="r_uarm" pos="0 -0.187 -0.016">
                                <inertial pos="0 0.065 0" quat="0.707107 0.707107 0 0" mass="4.386" diaginertia="0.00656 0.00656 0.00358" />
                                <joint name="r_arm_ely" pos="0 0 0" axis="0 1 0" limited="true" range="0 3.14159" damping="0.2" />
                                <geom size="0.065 0.055" pos="0 -0.035 0" quat="0.707105 0.707108 0 0" type="cylinder" />
                                <geom size="0.047 0.071" pos="-0.005 -0.111 0.017" quat="0.707105 0 0.707108 0" type="cylinder" />
                                <geom size="0.025 0.035 0.075" pos="-0.001 -0.043 0.01" quat="0.707107 0 0.707107 0" type="box" />
                                <body name="r_larm" pos="0 -0.119 0.0092">
                                    <inertial pos="0 0 0" quat="0.5 0.5 0.5 0.5" mass="3.248" diaginertia="0.00446 0.00446 0.00265" />
                                    <joint name="r_arm_elx" pos="0 0 0" axis="1 0 0" limited="true" range="-2.35619 0" damping="0.2" />
                                    <geom size="0.045 0.0625" pos="0.001 -0.127 0" quat="0.707107 0.707107 0 0" type="cylinder" />
                                    <geom size="0.0675 0.075 0.03" pos="0.001 -0.051 0" type="box" />
                                    <body name="r_ufarm" pos="0 -0.187 -0.0092">
                                        <inertial pos="0 0.065 0" quat="0.707107 0.707107 0 0" mass="4.386" diaginertia="0.00656 0.00656 0.00358" />
                                        <joint name="r_arm_wry" pos="0 0 0" axis="0 1 0" limited="true" range="0 3.14159" damping="0.1" />
                                        <geom size="0.045 0.0625" pos="0 -0.13 0.004" quat="0.707105 0 0.707108 0" type="cylinder" />
                                        <geom size="0.0675 0.05 0.0225" pos="0.001 -0.053 -0.002" type="box" />
                                        <body name="r_lfarm" pos="0 -0.119 0.0092">
                                            <inertial pos="0 0 0" quat="0.5 0.5 0.5 0.5" mass="2.509" diaginertia="0.00446 0.00446 0.00265" />
                                            <joint name="r_arm_wrx" pos="0 0 0" axis="1 0 0" limited="true" range="-1.1781 1.1781" damping="0.1" />
                                            <geom size="0.03 0.025" pos="0.001 -0.1 -0.01" quat="0.707107 0.707107 0 0" type="cylinder" />
                                            <geom size="0.065 0.045 0.035" pos="0.001 -0.05 -0.01" type="box" />
                                            <body name="r_hand" pos="0 0 0">
                                                <inertial pos="0 0 0" mass="1" diaginertia="0.0001 0.0001 0.0001" />
                                                <joint name="r_arm_wry2" pos="0 0 0" axis="0 1 0" limited="true" range="-0.001 0.001" damping="0.1" />
                                                <geom size="0.03" pos="0 -0.15 -0.01" rgba="1 1 1 1" />
                                            </body>
                                        </body>
                                    </body>
                                </body>
                            </body>
                        </body>
                    </body>
                </body>
            </body>
        </body>
        <body name="l_uglut" pos="0 0.089 0">
            <inertial pos="0.00529262 -0.00344732 0.00313046" quat="0.999122 -7.72169e-05 0.0419028 -0.000305187" mass="1.959" diaginertia="0.000745109 0.000688179 0.000410071" />
            <joint name="l_leg_hpz" pos="0 0 0" axis="0 0 1" limited="true" range="-0.174358 0.786794" damping="0.1" />
            <geom size="0.025 0.05 0.05" pos="0.01 0.005 0" quat="0.965694 0.259684 0 0" type="box" />
            <geom size="0.019841 0.040421" type="cylinder" />
            <body name="l_lglut" pos="0 0 0">
                <inertial pos="0.0133341 0.0170484 -0.0312052" quat="0.353465 0.600383 0.388609 0.602981" mass="0.898" diaginertia="0.00133867 0.000995812 0.000690275" />
                <joint name="l_leg_hpx" pos="0 0 0" axis="1 0 0" limited="true" range="-0.523599 0.523599" damping="0.1" />
                <geom size="0.0625 0.025 0.04" pos="0.015 0.026 -0.028" type="box" />
                <geom size="0.0200969 0.030153" pos="0.05 0.027488 -0.067" quat="0.707107 0.707107 0 0" type="cylinder" />
                <geom size="0.02 0.072" pos="0.0115 0 0" quat="0.707107 0 0.707107 0" type="cylinder" />
                <body name="l_uleg" pos="0.05 0.0225 -0.066">
                    <inertial pos="0 0 -0.21" mass="8.204" diaginertia="0.09 0.09 0.02" />
                    <joint name="l_leg_hpy" pos="0 0 0" axis="0 1 0" limited="true" range="-1.61234 0.65764" damping="0.1" />
                    <geom size="0.09 0.075" pos="-0.0199 0.00585 -0.122" type="cylinder" />
                    <geom size="0.07 0.075" pos="-0.032 -0.005 -0.224" quat="0.988771 0 -0.149438 0" type="cylinder" />
                    <geom size="0.05 0.075" pos="0.003 0.015 -0.254" quat="0.995083 -0.0747715 0.0647716 0.004867" type="cylinder" />
                    <geom size="0.035 0.019 0.075" pos="-0.007 -0.053 -0.052" type="box" />
                    <geom size="0.035 0.019 0.07" pos="-0.017 0.0595 -0.049" type="box" />
                    <body name="l_lleg" pos="-0.05 0 -0.374">
                        <inertial pos="0.001 0 -0.187" quat="0.999751 0 0.0223266 0" mass="4.515" diaginertia="0.0771341 0.076 0.00986594" />
                        <joint name="l_leg_kny" pos="0 0 0" axis="0 1 0" limited="true" range="0 2.35637" damping="0.2" />
                        <geom size="0.07 0.2" pos="0.02 0.00295 -0.182" quat="0.99875 0 0.0499792 0" type="cylinder" />
                        <body name="l_talus" pos="0 0 -0.422">
                            <inertial pos="0 0 0" quat="0.5 0.5 -0.5 0.5" mass="0.125" diaginertia="1.30101e-05 1.01674e-05 8.42775e-06" />
                            <joint name="l_leg_aky" pos="0 0 0" axis="0 1 0" limited="true" range="-1 0.7" damping="0.1" />
                            <geom size="0.010181 0.014771" quat="0.707107 0 0.707107 0" type="cylinder" />
                            <geom size="0.010348 0.0050295" quat="0.707107 0.707107 0 0" type="cylinder" />
                            <body name="l_foot" pos="0 0 0">
                                <inertial pos="0.027 0 -0.067" quat="0 0.707107 0 0.707107" mass="2.41" diaginertia="0.008 0.007 0.002" />
                                <joint name="l_leg_akx" pos="0 0 0" axis="1 0 0" limited="true" range="-0.8 0.8" damping="0.1" />
                                <geom size="0.1135 0.0669435 0.025" pos="0.023 0 -0.049119" type="box" />
                                <geom size="0.05 0.04 0.01" pos="0.1225 0 -0.0641" type="box" />
                            </body>
                        </body>
                    </body>
                </body>
            </body>
        </body>
        <body name="r_uglut" pos="0 -0.089 0">
            <inertial pos="0.00529262 0.00344732 0.00313046" quat="0.999122 7.72169e-05 0.0419028 0.000305187" mass="1.959" diaginertia="0.000745109 0.000688179 0.000410071" />
            <joint name="r_leg_hpz" pos="0 0 0" axis="0 0 1" limited="true" range="-0.786794 0.174358" damping="0.1" />
            <geom size="0.025 0.05 0.05" pos="0.01 -0.005 0" quat="0.965694 -0.259684 0 0" type="box" />
            <geom size="0.019841 0.040421" type="cylinder" />
            <body name="r_lglut" pos="0 0 0">
                <inertial pos="0.0133341 -0.0170484 -0.0312052" quat="0.602981 0.388609 0.600383 0.353465" mass="0.898" diaginertia="0.00133867 0.000995812 0.000690275" />
                <joint name="r_leg_hpx" pos="0 0 0" axis="1 0 0" limited="true" range="-0.523599 0.523599" damping="0.1" />
                <geom size="0.0625 0.025 0.04" pos="0.015 -0.026 -0.028" type="box" />
                <geom size="0.0200969 0.030153" pos="0.05 -0.027488 -0.067" quat="0.707107 0.707107 0 0" type="cylinder" />
                <geom size="0.02 0.071" pos="0.0105 0 0" quat="0.707107 0 0.707107 0" type="cylinder" />
                <body name="r_uleg" pos="0.05 -0.0225 -0.066">
                    <inertial pos="0 0 -0.21" mass="8.204" diaginertia="0.09 0.09 0.02" />
                    <joint name="r_leg_hpy" pos="0 0 0" axis="0 1 0" limited="true" range="-1.61234 0.65764" damping="0.1" />
                    <geom size="0.09 0.075" pos="-0.0199 -0.00585 -0.122" type="cylinder" />
                    <geom size="0.07 0.075" pos="-0.032 0.005 -0.224" quat="0.988771 0 -0.149438 0" type="cylinder" />
                    <geom size="0.05 0.075" pos="0.003 -0.015 -0.254" quat="0.995083 0.0747715 0.0647716 -0.004867" type="cylinder" />
                    <geom size="0.035 0.019 0.075" pos="-0.007 0.053 -0.052" type="box" />
                    <geom size="0.035 0.019 0.07" pos="-0.017 -0.0595 -0.049" type="box" />
                    <body name="r_lleg" pos="-0.05 0 -0.374">
                        <inertial pos="0.001 0 -0.187" quat="0.999751 0 0.0223266 0" mass="4.515" diaginertia="0.0771341 0.076 0.00986594" />
                        <joint name="r_leg_kny" pos="0 0 0" axis="0 1 0" limited="true" range="0 2.35637" damping="0.2" />
                        <geom size="0.07 0.2" pos="0.02 -0.00295 -0.182" quat="0.99875 0 0.0499792 0" type="cylinder" />
                        <body name="r_talus" pos="0 0 -0.422">
                            <inertial pos="0 0 0" quat="0.5 0.5 -0.5 0.5" mass="0.125" diaginertia="1.30101e-05 1.01674e-05 8.42775e-06" />
                            <joint name="r_leg_aky" pos="0 0 0" axis="0 1 0" limited="true" range="-1 0.7" damping="0.1" />
                            <geom size="0.010181 0.014771" quat="0.707107 0 0.707107 0" type="cylinder" />
                            <geom size="0.010348 0.0050295" quat="0.707107 0.707107 0 0" type="cylinder" />
                            <body name="r_foot" pos="0 0 0">
                                <inertial pos="0.027 0 -0.067" quat="0 0.707107 0 0.707107" mass="2.41" diaginertia="0.008 0.007 0.002" />
                                <joint name="r_leg_akx" pos="0 0 0" axis="1 0 0" limited="true" range="-0.8 0.8" damping="0.1" />
                                <geom size="0.1135 0.0669435 0.025" pos="0.023 0 -0.049119" type="box" />
                                <geom size="0.05 0.04 0.01" pos="0.1225 0 -0.0641" type="box" />
                            </body>
                        </body>
                    </body>
                </body>
            </body>
        </body>
    </worldbody>
</mujoco>
